Ошибка ТГ: последовательная тактика
Ошибка:
Traceback (most recent call last):
  File "main.py", line 182, in findPath
    search_result = path.search(matrix_tg, self.startTG_coordinate, self.endTG_coordinate)
  File "/home/serge/Документы/Python3/Makovey/Makovey/path.py", line 58, in search
    start_node = Node(None, tuple(start[::-1]))
TypeError: 'NoneType' object is not subscriptable


Ошибка взаимодействия ТГ и нарушителя
Ошибка:
Traceback (most recent call last):
  File "main.py", line 230, in findPath
    self.meet_point = self.detectIntruder(intruder_least_path, intruder_cost, tg_least_path, tg_cost)
UnboundLocalError: local variable 'tg_cost' referenced before assignment


Невозможно нарисовать путь тревожной группы
Ошибка:
Traceback (most recent call last):
  File "main.py", line 286, in drawPath
    for position in finded_tg_path:
TypeError: 'NoneType' object is not iterable


Нет места встречи нарушителя и ТГ
Ошибка:
Traceback (most recent call last):
  File "main.py", line 304, in drawPath
    self.drawMeeting(self.meet_point)
AttributeError: 'App' object has no attribute 'meet_point'


Путь не найден
Ошибка:
Traceback (most recent call last):
  File "main.py", line 240, in findPath
    self.outputLabel.setText(f'{self.outputLabel.text()}\n'
UnboundLocalError: local variable 'tg_cost' referenced before assignment


